Workbook

Sheet 数据源
A1: 日 期 | B1: 班次 | C1: 机床号 | D1: 图 号 | E1: 零件名称 | F1: 校对 | G1: 版次 | H1: 工 序 | I1: 工序内容 | J1: 计划数量 | K1: 完成数量 | L1: 首检 | M1: 批检 | N1: 质量编号 | O1: 输入程序时间 | P1: 程序时间 | Q1: 准备工时 | R1: 输入准备工时 | S1: 调序 | T1: 辅助工时 | U1: 合计 | V1: 操作者 | W1: 备注 | X1: 负责人签字
A2: 1/3 | D2: CB2284460-007-001 | E2: 四通接头 | F2: =+VLOOKUP(D2,[1]Sheet1!$D$2:$E$29166,2,0) -> 四通接头 | G2: B | H2: 65 | I2: =INDEX([2]Sheet1!$F$1:$AF$65808,MATCH(D2&G2&I$1,[2]Sheet1!$B$1:$B$65808&[2]Sheet1!$D$1:$D$65808&[2]Sheet1!$E$1:$E$65808,0),MATCH(H2,[2]Sheet1!$F$1:$AF$1,0)) -> #VALUE! | J2: 8 | K2: 8 | L2: 8 | M2: 8 | N2: 6P001 6P003 | P2: {=IFERROR(INDEX([2]Sheet1!$F$1:$AF$65808,MATCH($D2&$G2&P$1,[2]Sheet1!$B$1:$B$65808&[2]Sheet1!$D$1:$D$65808&[2]Sheet1!$E$1:$E$65808,0),MATCH($H2,[2]Sheet1!$F$1:$AF$1,0)),0)} -> 35 | U2: =ROUND((K2*P2+Q2*S2)/60+T2,1) -> 4.7 | V2: 毛波
A3: 1/4 | D3: DD-J10-21102-33-Z | E3: 10460上接头 | F3: =+VLOOKUP(D3,[1]Sheet1!$D$2:$E$29166,2,0) -> 10460上接头 | G3: D | H3: 40 | I3: {=INDEX([2]Sheet1!$F$1:$AF$65808,MATCH(D3&G3&I$1,[2]Sheet1!$B$1:$B$65808&[2]Sheet1!$D$1:$D$65808&[2]Sheet1!$E$1:$E$65808,0),MATCH(H3,[2]Sheet1!$F$1:$AF$1,0))} -> 40/钳工 | J3: 2 | K3: 2 | L3: 30 | M3: 30 | N3: C7P007-C7P008 | P3: {=IFERROR(INDEX([2]Sheet1!$F$1:$AF$65808,MATCH($D3&$G3&P$1,[2]Sheet1!$B$1:$B$65808&[2]Sheet1!$D$1:$D$65808&[2]Sheet1!$E$1:$E$65808,0),MATCH($H3,[2]Sheet1!$F$1:$AF$1,0)),0)} -> 15 | U3: =ROUND((K3*P3+Q3*S3)/60+T3,1) -> 0.5 | V3: 毛波
A4: 1/5 | D4: CB221T3LG-002-001 | E4: 接头 | F4: =+VLOOKUP(D4,[1]Sheet1!$D$2:$E$29166,2,0) -> 接头 | G4: B | H4: 10 | I4: {=INDEX([2]Sheet1!$F$1:$AF$65808,MATCH(D4&G4&I$1,[2]Sheet1!$B$1:$B$65808&[2]Sheet1!$D$1:$D$65808&[2]Sheet1!$E$1:$E$65808,0),MATCH(H4,[2]Sheet1!$F$1:$AF$1,0))} -> 10/钳工 | J4: 5 | K4: 5 | L4: 8 | M4: 8 | N4: 6P001 | P4: {=IFERROR(INDEX([2]Sheet1!$F$1:$AF$65808,MATCH($D4&$G4&P$1,[2]Sheet1!$B$1:$B$65808&[2]Sheet1!$D$1:$D$65808&[2]Sheet1!$E$1:$E$65808,0),MATCH($H4,[2]Sheet1!$F$1:$AF$1,0)),0)} -> 15 | U4: =ROUND((K4*P4+Q4*S4)/60+T4,1) -> 1.3 | V4: 毛波 | W4: Q 去毛刺 打钢印 5根料
A5: 1/7 | D5: CB22836Y6-003-001 | E5: 轴 | F5: =+VLOOKUP(D5,[1]Sheet1!$D$2:$E$29166,2,0) -> 轴 | G5: B | H5: 15 | I5: {=INDEX([2]Sheet1!$F$1:$AF$65808,MATCH(D5&G5&I$1,[2]Sheet1!$B$1:$B$65808&[2]Sheet1!$D$1:$D$65808&[2]Sheet1!$E$1:$E$65808,0),MATCH(H5,[2]Sheet1!$F$1:$AF$1,0))} -> 15/钳工 | J5: 2 | K5: 2 | L5: 8 | M5: 8 | N5: 1P004 2P004 | P5: {=IFERROR(INDEX([2]Sheet1!$F$1:$AF$65808,MATCH($D5&$G5&P$1,[2]Sheet1!$B$1:$B$65808&[2]Sheet1!$D$1:$D$65808&[2]Sheet1!$E$1:$E$65808,0),MATCH($H5,[2]Sheet1!$F$1:$AF$1,0)),0)} -> 4 | U5: =ROUND((K5*P5+Q5*S5)/60+T5,1) -> 0.1 | V5: 毛波
A6: 1/7 | D6: CB2283664-002-001 | E6: 法兰 | F6: =+VLOOKUP(D6,[1]Sheet1!$D$2:$E$29166,2,0) -> 法兰 | G6: C | H6: 35 | I6: {=INDEX([2]Sheet1!$F$1:$AF$65808,MATCH(D6&G6&I$1,[2]Sheet1!$B$1:$B$65808&[2]Sheet1!$D$1:$D$65808&[2]Sheet1!$E$1:$E$65808,0),MATCH(H6,[2]Sheet1!$F$1:$AF$1,0))} -> 35/钳工 | J6: 80 | K6: 80 | L6: 8 | M6: 8 | N6: 6P001 | P6: {=IFERROR(INDEX([2]Sheet1!$F$1:$AF$65808,MATCH($D6&$G6&P$1,[2]Sheet1!$B$1:$B$65808&[2]Sheet1!$D$1:$D$65808&[2]Sheet1!$E$1:$E$65808,0),MATCH($H6,[2]Sheet1!$F$1:$AF$1,0)),0)} -> 25 | U6: =ROUND((K6*P6+Q6*S6)/60+T6,1) -> 33.3 | V6: 毛波
A7: 1/8 | D7: DD-J10-21102-32-Y | E7: 10060下接头 | F7: =+VLOOKUP(D7,[1]Sheet1!$D$2:$E$29166,2,0) -> 10060下接头 | G7: D | H7: 40 | I7: {=INDEX([2]Sheet1!$F$1:$AF$65808,MATCH(D7&G7&I$1,[2]Sheet1!$B$1:$B$65808&[2]Sheet1!$D$1:$D$65808&[2]Sheet1!$E$1:$E$65808,0),MATCH(H7,[2]Sheet1!$F$1:$AF$1,0))} -> 40/钳工 | J7: 2 | K7: 2 | L7: 30 | M7: 30 | N7: C7P001 C7P002 | P7: {=IFERROR(INDEX([2]Sheet1!$F$1:$AF$65808,MATCH($D7&$G7&P$1,[2]Sheet1!$B$1:$B$65808&[2]Sheet1!$D$1:$D$65808&[2]Sheet1!$E$1:$E$65808,0),MATCH($H7,[2]Sheet1!$F$1:$AF$1,0)),0)} -> 15 | U7: =ROUND((K7*P7+Q7*S7)/60+T7,1) -> 0.5 | V7: 毛波
A8: 1/8 | D8: CB5350500-010L006 | E8: 1号护板维型肋左件 | F8: =+VLOOKUP(D8,[1]Sheet1!$D$2:$E$29166,2,0) -> 1号护板维型肋左件 | G8: B | H8: 35 | I8: {=INDEX([2]Sheet1!$F$1:$AF$65808,MATCH(D8&G8&I$1,[2]Sheet1!$B$1:$B$65808&[2]Sheet1!$D$1:$D$65808&[2]Sheet1!$E$1:$E$65808,0),MATCH(H8,[2]Sheet1!$F$1:$AF$1,0))} -> 35/钳工 | J8: 23 | K8: 23 | L8: 8 | M8: 8 | N8: 6P001 | P8: {=IFERROR(INDEX([2]Sheet1!$F$1:$AF$65808,MATCH($D8&$G8&P$1,[2]Sheet1!$B$1:$B$65808&[2]Sheet1!$D$1:$D$65808&[2]Sheet1!$E$1:$E$65808,0),MATCH($H8,[2]Sheet1!$F$1:$AF$1,0)),0)} -> 45 | U8: =ROUND((K8*P8+Q8*S8)/60+T8,1) -> 17.3 | V8: 毛波
A9: 1/9 | D9: CB2747GA0-002-002 | E9: 扩压式管接头 | F9: =+VLOOKUP(D9,[1]Sheet1!$D$2:$E$29166,2,0) -> 扩压式管接头 | G9: C | H9: 45 | I9: {=INDEX([2]Sheet1!$F$1:$AF$65808,MATCH(D9&G9&I$1,[2]Sheet1!$B$1:$B$65808&[2]Sheet1!$D$1:$D$65808&[2]Sheet1!$E$1:$E$65808,0),MATCH(H9,[2]Sheet1!$F$1:$AF$1,0))} -> 45/钳工 | J9: 30 | K9: 30 | L9: 8 | M9: 8 | N9: 6P001 | P9: {=IFERROR(INDEX([2]Sheet1!$F$1:$AF$65808,MATCH($D9&$G9&P$1,[2]Sheet1!$B$1:$B$65808&[2]Sheet1!$D$1:$D$65808&[2]Sheet1!$E$1:$E$65808,0),MATCH($H9,[2]Sheet1!$F$1:$AF$1,0)),0)} -> 40 | U9: =ROUND((K9*P9+Q9*S9)/60+T9,1) -> 20 | V9: 毛波
A10: 1/11 | D10: DD-J10B-94076-2031/3 | E10: 接管嘴 | F10: =+VLOOKUP(D10,[1]Sheet1!$D$2:$E$29166,2,0) -> 接管嘴 | G10: B | H10: 35 | I10: {=INDEX([2]Sheet1!$F$1:$AF$65808,MATCH(D10&G10&I$1,[2]Sheet1!$B$1:$B$65808&[2]Sheet1!$D$1:$D$65808&[2]Sheet1!$E$1:$E$65808,0),MATCH(H10,[2]Sheet1!$F$1:$AF$1,0))} -> 35/钳工 | J10: 29 | K10: 29 | L10: 8 | M10: 8 | N10: 6P003 6P005 | P10: {=IFERROR(INDEX([2]Sheet1!$F$1:$AF$65808,MATCH($D10&$G10&P$1,[2]Sheet1!$B$1:$B$65808&[2]Sheet1!$D$1:$D$65808&[2]Sheet1!$E$1:$E$65808,0),MATCH($H10,[2]Sheet1!$F$1:$AF$1,0)),0)} -> 35 | U10: =ROUND((K10*P10+Q10*S10)/60+T10,1) -> 16.9 | V10: 毛波
A11: 1/11 | D11: 5317C23409G70 | E11: 立柱加强接头 | F11: =+VLOOKUP(D11,[1]Sheet1!$D$2:$E$29166,2,0) -> 立柱加强接头 | G11: A | H11: 35 | I11: {=INDEX([2]Sheet1!$F$1:$AF$65808,MATCH(D11&G11&I$1,[2]Sheet1!$B$1:$B$65808&[2]Sheet1!$D$1:$D$65808&[2]Sheet1!$E$1:$E$65808,0),MATCH(H11,[2]Sheet1!$F$1:$AF$1,0))} -> 35钳工 | J11: 9 | K11: 9 | L11: 8 | M11: 8 | N11: 3A | P11: {=IFERROR(INDEX([2]Sheet1!$F$1:$AF$65808,MATCH($D11&$G11&P$1,[2]Sheet1!$B$1:$B$65808&[2]Sheet1!$D$1:$D$65808&[2]Sheet1!$E$1:$E$65808,0),MATCH($H11,[2]Sheet1!$F$1:$AF$1,0)),0)} -> 50 | U11: =ROUND((K11*P11+Q11*S11)/60+T11,1) -> 7.5 | V11: 毛波
A12: 1/12 | D12: DD-J10B-94076-501-Y | E12: 拉杆支座 | F12: =+VLOOKUP(D12,[1]Sheet1!$D$2:$E$29166,2,0) -> 拉杆支座 | G12: B | H12: 80 | I12: {=INDEX([2]Sheet1!$F$1:$AF$65808,MATCH(D12&G12&I$1,[2]Sheet1!$B$1:$B$65808&[2]Sheet1!$D$1:$D$65808&[2]Sheet1!$E$1:$E$65808,0),MATCH(H12,[2]Sheet1!$F$1:$AF$1,0))} -> 80/检验 | J12: 12 | K12: 12 | L12: 8 | M12: 8 | N12: 6P005 | P12: {=IFERROR(INDEX([2]Sheet1!$F$1:$AF$65808,MATCH($D12&$G12&P$1,[2]Sheet1!$B$1:$B$65808&[2]Sheet1!$D$1:$D$65808&[2]Sheet1!$E$1:$E$65808,0),MATCH($H12,[2]Sheet1!$F$1:$AF$1,0)),0)} -> 0 | U12: =ROUND((K12*P12+Q12*S12)/60+T12,1) -> 0 | V12: 毛波
A13: 1/12 | D13: DD-J10B-61041-18 | E13: 管接头 | F13: =+VLOOKUP(D13,[1]Sheet1!$D$2:$E$29166,2,0) -> 管接头 | G13: C | H13: 35 | I13: {=INDEX([2]Sheet1!$F$1:$AF$65808,MATCH(D13&G13&I$1,[2]Sheet1!$B$1:$B$65808&[2]Sheet1!$D$1:$D$65808&[2]Sheet1!$E$1:$E$65808,0),MATCH(H13,[2]Sheet1!$F$1:$AF$1,0))} -> 35/钳工 | J13: 60 | K13: 60 | L13: 8 | M13: 8 | N13: 6P004 | P13: {=IFERROR(INDEX([2]Sheet1!$F$1:$AF$65808,MATCH($D13&$G13&P$1,[2]Sheet1!$B$1:$B$65808&[2]Sheet1!$D$1:$D$65808&[2]Sheet1!$E$1:$E$65808,0),MATCH($H13,[2]Sheet1!$F$1:$AF$1,0)),0)} -> 30 | U13: =ROUND((K13*P13+Q13*S13)/60+T13,1) -> 30 | V13: 毛波
A14: 1/13 | D14: CB5811100-010-001 | E14: 螺栓 | F14: =+VLOOKUP(D14,[1]Sheet1!$D$2:$E$29166,2,0) -> 螺栓 | G14: C | H14: 50 | I14: {=INDEX([2]Sheet1!$F$1:$AF$65808,MATCH(D14&G14&I$1,[2]Sheet1!$B$1:$B$65808&[2]Sheet1!$D$1:$D$65808&[2]Sheet1!$E$1:$E$65808,0),MATCH(H14,[2]Sheet1!$F$1:$AF$1,0))} -> 50/钳工 | J14: 20 | K14: 20 | L14: 8 | M14: 8 | N14: 6P001 | P14: {=IFERROR(INDEX([2]Sheet1!$F$1:$AF$65808,MATCH($D14&$G14&P$1,[2]Sheet1!$B$1:$B$65808&[2]Sheet1!$D$1:$D$65808&[2]Sheet1!$E$1:$E$65808,0),MATCH($H14,[2]Sheet1!$F$1:$AF$1,0)),0)} -> 25 | U14: =ROUND((K14*P14+Q14*S14)/60+T14,1) -> 8.3 | V14: 毛波
A15: 1/13 | D15: C256300800-003-001 | E15: 垫圈 | F15: =+VLOOKUP(D15,[1]Sheet1!$D$2:$E$29166,2,0) -> 垫圈 | G15: A | H15: 10 | I15: {=INDEX([2]Sheet1!$F$1:$AF$65808,MATCH(D15&G15&I$1,[2]Sheet1!$B$1:$B$65808&[2]Sheet1!$D$1:$D$65808&[2]Sheet1!$E$1:$E$65808,0),MATCH(H15,[2]Sheet1!$F$1:$AF$1,0))} -> 10钳工 | J15: 2 | K15: 2 | L15: 8 | M15: 8 | N15: 00P001 | P15: {=IFERROR(INDEX([2]Sheet1!$F$1:$AF$65808,MATCH($D15&$G15&P$1,[2]Sheet1!$B$1:$B$65808&[2]Sheet1!$D$1:$D$65808&[2]Sheet1!$E$1:$E$65808,0),MATCH($H15,[2]Sheet1!$F$1:$AF$1,0)),0)} -> 4 | U15: =ROUND((K15*P15+Q15*S15)/60+T15,1) -> 0.1 | V15: 毛波 | W15: D 打钢印 2根料
A16: 1/13 | D16: 5319C96017G70 | E16: 短框连接块 | F16: =+VLOOKUP(D16,[1]Sheet1!$D$2:$E$29166,2,0) -> 短框连接块 | G16: A | H16: 30 | I16: {=INDEX([2]Sheet1!$F$1:$AF$65808,MATCH(D16&G16&I$1,[2]Sheet1!$B$1:$B$65808&[2]Sheet1!$D$1:$D$65808&[2]Sheet1!$E$1:$E$65808,0),MATCH(H16,[2]Sheet1!$F$1:$AF$1,0))} -> 30/钳工 | J16: 8 | K16: 8 | L16: 8 | M16: 8 | N16: 3A | P16: {=IFERROR(INDEX([2]Sheet1!$F$1:$AF$65808,MATCH($D16&$G16&P$1,[2]Sheet1!$B$1:$B$65808&[2]Sheet1!$D$1:$D$65808&[2]Sheet1!$E$1:$E$65808,0),MATCH($H16,[2]Sheet1!$F$1:$AF$1,0)),0)} -> 50 | U16: =ROUND((K16*P16+Q16*S16)/60+T16,1) -> 6.7 | V16: 毛波
A17: 1/13 | D17: DD-J10-21102-32-Y | E17: 10060下接头 | F17: =+VLOOKUP(D17,[1]Sheet1!$D$2:$E$29166,2,0) -> 10060下接头 | G17: D | H17: 40 | I17: {=INDEX([2]Sheet1!$F$1:$AF$65808,MATCH(D17&G17&I$1,[2]Sheet1!$B$1:$B$65808&[2]Sheet1!$D$1:$D$65808&[2]Sheet1!$E$1:$E$65808,0),MATCH(H17,[2]Sheet1!$F$1:$AF$1,0))} -> 40/钳工 | J17: 6 | K17: 6 | L17: 30 | M17: 30 | N17: C7P003-C7P008 | P17: {=IFERROR(INDEX([2]Sheet1!$F$1:$AF$65808,MATCH($D17&$G17&P$1,[2]Sheet1!$B$1:$B$65808&[2]Sheet1!$D$1:$D$65808&[2]Sheet1!$E$1:$E$65808,0),MATCH($H17,[2]Sheet1!$F$1:$AF$1,0)),0)} -> 15 | U17: =ROUND((K17*P17+Q17*S17)/60+T17,1) -> 1.5 | V17: 毛波
A18: 1/14 | D18: DD-J10-61101-5001/16 | E18: 管接头 | F18: =+VLOOKUP(D18,[1]Sheet1!$D$2:$E$29166,2,0) -> 管接头 | G18: C | H18: 35 | I18: {=INDEX([2]Sheet1!$F$1:$AF$65808,MATCH(D18&G18&I$1,[2]Sheet1!$B$1:$B$65808&[2]Sheet1!$D$1:$D$65808&[2]Sheet1!$E$1:$E$65808,0),MATCH(H18,[2]Sheet1!$F$1:$AF$1,0))} -> 35/钳工 | J18: 20 | K18: 20 | L18: 8 | M18: 8 | N18: C6P004 | P18: {=IFERROR(INDEX([2]Sheet1!$F$1:$AF$65808,MATCH($D18&$G18&P$1,[2]Sheet1!$B$1:$B$65808&[2]Sheet1!$D$1:$D$65808&[2]Sheet1!$E$1:$E$65808,0),MATCH($H18,[2]Sheet1!$F$1:$AF$1,0)),0)} -> 30 | U18: =ROUND((K18*P18+Q18*S18)/60+T18,1) -> 10 | V18: 毛波
A19: 1/15 | D19: DD-J10-61052-172 | E19: 接管嘴 | F19: =+VLOOKUP(D19,[1]Sheet1!$D$2:$E$29166,2,0) -> 接管嘴 | G19: B | H19: 30 | I19: {=INDEX([2]Sheet1!$F$1:$AF$65808,MATCH(D19&G19&I$1,[2]Sheet1!$B$1:$B$65808&[2]Sheet1!$D$1:$D$65808&[2]Sheet1!$E$1:$E$65808,0),MATCH(H19,[2]Sheet1!$F$1:$AF$1,0))} -> 30/钳工 | J19: 60 | K19: 60 | L19: 8 | M19: 8 | N19: C6P005 | P19: {=IFERROR(INDEX([2]Sheet1!$F$1:$AF$65808,MATCH($D19&$G19&P$1,[2]Sheet1!$B$1:$B$65808&[2]Sheet1!$D$1:$D$65808&[2]Sheet1!$E$1:$E$65808,0),MATCH($H19,[2]Sheet1!$F$1:$AF$1,0)),0)} -> 25 | U19: =ROUND((K19*P19+Q19*S19)/60+T19,1) -> 25 | V19: 毛波
A20: 1/15 | D20: C221069811-001-001 | E20: 平管嘴 | F20: =+VLOOKUP(D20,[1]Sheet1!$D$2:$E$29166,2,0) -> 平管嘴 | G20: A | H20: 10 | I20: {=INDEX([2]Sheet1!$F$1:$AF$65808,MATCH(D20&G20&I$1,[2]Sheet1!$B$1:$B$65808&[2]Sheet1!$D$1:$D$65808&[2]Sheet1!$E$1:$E$65808,0),MATCH(H20,[2]Sheet1!$F$1:$AF$1,0))} -> 10钳工 | J20: 14 | K20: 14 | L20: 8 | M20: 8 | N20: 00P001 00P002 | P20: {=IFERROR(INDEX([2]Sheet1!$F$1:$AF$65808,MATCH($D20&$G20&P$1,[2]Sheet1!$B$1:$B$65808&[2]Sheet1!$D$1:$D$65808&[2]Sheet1!$E$1:$E$65808,0),MATCH($H20,[2]Sheet1!$F$1:$AF$1,0)),0)} -> 4 | U20: =ROUND((K20*P20+Q20*S20)/60+T20,1) -> 0.9 | V20: 毛波
A21: 1/16 | D21: CB5811100-010-001 | E21: 螺栓 | F21: =+VLOOKUP(D21,[1]Sheet1!$D$2:$E$29166,2,0) -> 螺栓 | G21: C | H21: 70 | I21: {=INDEX([2]Sheet1!$F$1:$AF$65808,MATCH(D21&G21&I$1,[2]Sheet1!$B$1:$B$65808&[2]Sheet1!$D$1:$D$65808&[2]Sheet1!$E$1:$E$65808,0),MATCH(H21,[2]Sheet1!$F$1:$AF$1,0))} -> 0 | J21: 20 | K21: 20 | L21: 8 | M21: 8 | N21: 6P001 | P21: {=IFERROR(INDEX([2]Sheet1!$F$1:$AF$65808,MATCH($D21&$G21&P$1,[2]Sheet1!$B$1:$B$65808&[2]Sheet1!$D$1:$D$65808&[2]Sheet1!$E$1:$E$65808,0),MATCH($H21,[2]Sheet1!$F$1:$AF$1,0)),0)} -> 0 | U21: =ROUND((K21*P21+Q21*S21)/60+T21,1) -> 0 | V21: 毛波
A22: 1/16 | D22: CB221T2LN-001-001 | E22: 接管嘴 | F22: =+VLOOKUP(D22,[1]Sheet1!$D$2:$E$29166,2,0) -> 接管嘴 | G22: B | H22: 35 | I22: {=INDEX([2]Sheet1!$F$1:$AF$65808,MATCH(D22&G22&I$1,[2]Sheet1!$B$1:$B$65808&[2]Sheet1!$D$1:$D$65808&[2]Sheet1!$E$1:$E$65808,0),MATCH(H22,[2]Sheet1!$F$1:$AF$1,0))} -> 35/钳工 | J22: 19 | K22: 19 | L22: 8 | M22: 8 | N22: 6P001 | P22: {=IFERROR(INDEX([2]Sheet1!$F$1:$AF$65808,MATCH($D22&$G22&P$1,[2]Sheet1!$B$1:$B$65808&[2]Sheet1!$D$1:$D$65808&[2]Sheet1!$E$1:$E$65808,0),MATCH($H22,[2]Sheet1!$F$1:$AF$1,0)),0)} -> 15 | U22: =ROUND((K22*P22+Q22*S22)/60+T22,1) -> 4.8 | V22: 毛波
A23: 1/16 | D23: BC221T1BB-001-001 | E23: 法兰 | F23: =+VLOOKUP(D23,[1]Sheet1!$D$2:$E$29166,2,0) -> 法兰 | G23: C | H23: 50 | I23: {=INDEX([2]Sheet1!$F$1:$AF$65808,MATCH(D23&G23&I$1,[2]Sheet1!$B$1:$B$65808&[2]Sheet1!$D$1:$D$65808&[2]Sheet1!$E$1:$E$65808,0),MATCH(H23,[2]Sheet1!$F$1:$AF$1,0))} -> 50/钳工 | J23: 2 | K23: 2 | L23: 8 | M23: 8 | N23: 2P004 | P23: {=IFERROR(INDEX([2]Sheet1!$F$1:$AF$65808,MATCH($D23&$G23&P$1,[2]Sheet1!$B$1:$B$65808&[2]Sheet1!$D$1:$D$65808&[2]Sheet1!$E$1:$E$65808,0),MATCH($H23,[2]Sheet1!$F$1:$AF$1,0)),0)} -> 50 | U23: =ROUND((K23*P23+Q23*S23)/60+T23,1) -> 1.7 | V23: 毛波
A24: 1/16 | D24: DD-J10B-61201-12 | E24: 接头 | F24: =+VLOOKUP(D24,[1]Sheet1!$D$2:$E$29166,2,0) -> 接头 | G24: E | H24: 35 | I24: {=INDEX([2]Sheet1!$F$1:$AF$65808,MATCH(D24&G24&I$1,[2]Sheet1!$B$1:$B$65808&[2]Sheet1!$D$1:$D$65808&[2]Sheet1!$E$1:$E$65808,0),MATCH(H24,[2]Sheet1!$F$1:$AF$1,0))} -> 35/钳工 | J24: 21 | K24: 21 | L24: 8 | M24: 8 | N24: 7P003 | P24: {=IFERROR(INDEX([2]Sheet1!$F$1:$AF$65808,MATCH($D24&$G24&P$1,[2]Sheet1!$B$1:$B$65808&[2]Sheet1!$D$1:$D$65808&[2]Sheet1!$E$1:$E$65808,0),MATCH($H24,[2]Sheet1!$F$1:$AF$1,0)),0)} -> 20 | U24: =ROUND((K24*P24+Q24*S24)/60+T24,1) -> 7 | V24: 毛波
A25: 1/18 | D25: DD-J10B-94091-24G2 | E25: 20-28变径直通接头 | F25: =+VLOOKUP(D25,[1]Sheet1!$D$2:$E$29166,2,0) -> 20-28变径直通接头 | G25: B | H25: 10 | I25: {=INDEX([2]Sheet1!$F$1:$AF$65808,MATCH(D25&G25&I$1,[2]Sheet1!$B$1:$B$65808&[2]Sheet1!$D$1:$D$65808&[2]Sheet1!$E$1:$E$65808,0),MATCH(H25,[2]Sheet1!$F$1:$AF$1,0))} -> 10/钳毛刺 | J25: 20 | K25: 20 | L25: 8 | M25: 8 | N25: 6P004 | P25: {=IFERROR(INDEX([2]Sheet1!$F$1:$AF$65808,MATCH($D25&$G25&P$1,[2]Sheet1!$B$1:$B$65808&[2]Sheet1!$D$1:$D$65808&[2]Sheet1!$E$1:$E$65808,0),MATCH($H25,[2]Sheet1!$F$1:$AF$1,0)),0)} -> 10 | U25: =ROUND((K25*P25+Q25*S25)/60+T25,1) -> 3.3 | V25: 毛波
A26: 1/18 | D26: 5319C22035G70 | E26: 支架 | F26: =+VLOOKUP(D26,[1]Sheet1!$D$2:$E$29166,2,0) -> 支架 | G26: A | H26: 25 | I26: {=INDEX([2]Sheet1!$F$1:$AF$65808,MATCH(D26&G26&I$1,[2]Sheet1!$B$1:$B$65808&[2]Sheet1!$D$1:$D$65808&[2]Sheet1!$E$1:$E$65808,0),MATCH(H26,[2]Sheet1!$F$1:$AF$1,0))} -> 25钳工 | J26: 4 | K26: 4 | L26: 8 | M26: 8 | N26: 3A | P26: {=IFERROR(INDEX([2]Sheet1!$F$1:$AF$65808,MATCH($D26&$G26&P$1,[2]Sheet1!$B$1:$B$65808&[2]Sheet1!$D$1:$D$65808&[2]Sheet1!$E$1:$E$65808,0),MATCH($H26,[2]Sheet1!$F$1:$AF$1,0)),0)} -> 45 | U26: =ROUND((K26*P26+Q26*S26)/60+T26,1) -> 3 | V26: 毛波
A27: 1/3 | D27: CB5323210-005L065 | E27: 9350-11140左侧上梁 | F27: =+VLOOKUP(D27,[1]Sheet1!$D$2:$E$29166,2,0) -> 9350-11140左侧上梁 | G27: C | H27: 40 | I27: {=INDEX([2]Sheet1!$F$1:$AF$65808,MATCH(D27&G27&I$1,[2]Sheet1!$B$1:$B$65808&[2]Sheet1!$D$1:$D$65808&[2]Sheet1!$E$1:$E$65808,0),MATCH(H27,[2]Sheet1!$F$1:$AF$1,0))} -> #N/A | J27: 4 | K27: 4 | L27: 8 | M27: 8 | N27: 5P009 5P011 5P013 5P020 | P27: 1440 | U27: =ROUND((K27*P27+Q27*S27)/60+T27,1) -> 96 | V27: 曾云江/黄庆
A28: 1/4 | D28: XXX-600-00 | E28: XXXXXXX离心夹具3组合件 | F28: =+VLOOKUP(D28,[1]Sheet1!$D$2:$E$29166,2,0) -> XXXXXXX离心夹具3组合件 | G28: A | H28: 8 | I28: {=INDEX([2]Sheet1!$F$1:$AF$65808,MATCH(D28&G28&I$1,[2]Sheet1!$B$1:$B$65808&[2]Sheet1!$D$1:$D$65808&[2]Sheet1!$E$1:$E$65808,0),MATCH(H28,[2]Sheet1!$F$1:$AF$1,0))} -> #N/A | J28: 2 | K28: 2 | L28: 8 | M28: 8 | N28: 2020-10-N-75 | P28: 60 | U28: =ROUND((K28*P28+Q28*S28)/60+T28,1) -> 2 | V28: 曾云江
A29: 1/5 | D29: CB5327110-003R002 | E29: 8635右隔框 | F29: =+VLOOKUP(D29,[1]Sheet1!$D$2:$E$29166,2,0) -> 8635右隔框 | G29: E | H29: 35 | I29: {=INDEX([2]Sheet1!$F$1:$AF$65808,MATCH(D29&G29&I$1,[2]Sheet1!$B$1:$B$65808&[2]Sheet1!$D$1:$D$65808&[2]Sheet1!$E$1:$E$65808,0),MATCH(H29,[2]Sheet1!$F$1:$AF$1,0))} -> 35/钳工 | J29: 3 | K29: 3 | L29: 8 | M29: 8 | N29: 5P008 5P017-5P018 | P29: {=IFERROR(INDEX([2]Sheet1!$F$1:$AF$65808,MATCH($D29&$G29&P$1,[2]Sheet1!$B$1:$B$65808&[2]Sheet1!$D$1:$D$65808&[2]Sheet1!$E$1:$E$65808,0),MATCH($H29,[2]Sheet1!$F$1:$AF$1,0)),0)} -> 120 | U29: =ROUND((K29*P29+Q29*S29)/60+T29,1) -> 6 | V29: 曾云江
A30: 1/5 | D30: DD-J10S-06021-107 | E30: 后隔框 | F30: =+VLOOKUP(D30,[1]Sheet1!$D$2:$E$29166,2,0) -> 后隔框 | G30: A-1 | H30: 45 | I30: {=INDEX([2]Sheet1!$F$1:$AF$65808,MATCH(D30&G30&I$1,[2]Sheet1!$B$1:$B$65808&[2]Sheet1!$D$1:$D$65808&[2]Sheet1!$E$1:$E$65808,0),MATCH(H30,[2]Sheet1!$F$1:$AF$1,0))} -> 45/钳钻孔 | J30: 1 | K30: 1 | L30: 8 | M30: 8 | N30: 4P015 | P30: 960 | U30: =ROUND((K30*P30+Q30*S30)/60+T30,1) -> 16 | V30: 曾云江/黄庆
A31: 1/5 | D31: XXX-000-06 | E31: D 导向块 | F31: =+VLOOKUP(D31,[1]Sheet1!$D$2:$E$29166,2,0) -> 密封圈3 | H31: 35 | I31: {=INDEX([2]Sheet1!$F$1:$AF$65808,MATCH(D31&G31&I$1,[2]Sheet1!$B$1:$B$65808&[2]Sheet1!$D$1:$D$65808&[2]Sheet1!$E$1:$E$65808,0),MATCH(H31,[2]Sheet1!$F$1:$AF$1,0))} -> #N/A | J31: 2300 | K31: 1200 | L31: 8 | M31: 8 | N31: 2020-09-n-47 | P31: 15 | U31: =ROUND((K31*P31+Q31*S31)/60+T31,1) -> 300 | V31: 曾云江
A32: 1/8 | D32: CB5327110-003L002 | E32: 8635左隔框 | F32: =+VLOOKUP(D32,[1]Sheet1!$D$2:$E$29166,2,0) -> 8635左隔框 | G32: E | H32: 35 | I32: {=INDEX([2]Sheet1!$F$1:$AF$65808,MATCH(D32&G32&I$1,[2]Sheet1!$B$1:$B$65808&[2]Sheet1!$D$1:$D$65808&[2]Sheet1!$E$1:$E$65808,0),MATCH(H32,[2]Sheet1!$F$1:$AF$1,0))} -> 35/钳工 | J32: 3 | K32: 3 | L32: 8 | M32: 8 | N32: 5P002 5P016 5P018 | P32: {=IFERROR(INDEX([2]Sheet1!$F$1:$AF$65808,MATCH($D32&$G32&P$1,[2]Sheet1!$B$1:$B$65808&[2]Sheet1!$D$1:$D$65808&[2]Sheet1!$E$1:$E$65808,0),MATCH($H32,[2]Sheet1!$F$1:$AF$1,0)),0)} -> 120 | U32: =ROUND((K32*P32+Q32*S32)/60+T32,1) -> 6 | V32: 曾云江
A33: 1/8 | D33: CB5327110-003R002 | E33: 8635右隔框 | F33: =+VLOOKUP(D33,[1]Sheet1!$D$2:$E$29166,2,0) -> 8635右隔框 | G33: E | H33: 45 | I33: {=INDEX([2]Sheet1!$F$1:$AF$65808,MATCH(D33&G33&I$1,[2]Sheet1!$B$1:$B$65808&[2]Sheet1!$D$1:$D$65808&[2]Sheet1!$E$1:$E$65808,0),MATCH(H33,[2]Sheet1!$F$1:$AF$1,0))} -> 45/钳工 | J33: 3 | K33: 3 | L33: 30 | M33: 30 | N33: 5P008 5P017-5P018 | P33: {=IFERROR(INDEX([2]Sheet1!$F$1:$AF$65808,MATCH($D33&$G33&P$1,[2]Sheet1!$B$1:$B$65808&[2]Sheet1!$D$1:$D$65808&[2]Sheet1!$E$1:$E$65808,0),MATCH($H33,[2]Sheet1!$F$1:$AF$1,0)),0)} -> 480 | U33: =ROUND((K33*P33+Q33*S33)/60+T33,1) -> 24 | V33: 曾云江
A34: 1/9 | D34: CB5327110-003L002 | E34: 8635左隔框 | F34: =+VLOOKUP(D34,[1]Sheet1!$D$2:$E$29166,2,0) -> 8635左隔框 | G34: E | H34: 45 | I34: {=INDEX([2]Sheet1!$F$1:$AF$65808,MATCH(D34&G34&I$1,[2]Sheet1!$B$1:$B$65808&[2]Sheet1!$D$1:$D$65808&[2]Sheet1!$E$1:$E$65808,0),MATCH(H34,[2]Sheet1!$F$1:$AF$1,0))} -> 45/钳工 | J34: 3 | K34: 3 | L34: 30 | M34: 30 | N34: 5P002 5P016 5P018 | P34: {=IFERROR(INDEX([2]Sheet1!$F$1:$AF$65808,MATCH($D34&$G34&P$1,[2]Sheet1!$B$1:$B$65808&[2]Sheet1!$D$1:$D$65808&[2]Sheet1!$E$1:$E$65808,0),MATCH($H34,[2]Sheet1!$F$1:$AF$1,0)),0)} -> 480 | U34: =ROUND((K34*P34+Q34*S34)/60+T34,1) -> 24 | V34: 曾云江
A35: 1/9 | D35: CB5323210-005L065 | E35: 9350-11140左侧上梁 | F35: =+VLOOKUP(D35,[1]Sheet1!$D$2:$E$29166,2,0) -> 9350-11140左侧上梁 | G35: C | H35: 50 | I35: {=INDEX([2]Sheet1!$F$1:$AF$65808,MATCH(D35&G35&I$1,[2]Sheet1!$B$1:$B$65808&[2]Sheet1!$D$1:$D$65808&[2]Sheet1!$E$1:$E$65808,0),MATCH(H35,[2]Sheet1!$F$1:$AF$1,0))} -> #N/A | J35: 1 | K35: 1 | L35: 8 | M35: 8 | N35: 5P009 | P35: 1440 | U35: =ROUND((K35*P35+Q35*S35)/60+T35,1) -> 24 | V35: 曾云江/黄庆
A36: 1/12 | D36: CB5323210-005L065 | E36: 9350-11140左侧上梁 | F36: =+VLOOKUP(D36,[1]Sheet1!$D$2:$E$29166,2,0) -> 9350-11140左侧上梁 | G36: C | H36: 50 | I36: {=INDEX([2]Sheet1!$F$1:$AF$65808,MATCH(D36&G36&I$1,[2]Sheet1!$B$1:$B$65808&[2]Sheet1!$D$1:$D$65808&[2]Sheet1!$E$1:$E$65808,0),MATCH(H36,[2]Sheet1!$F$1:$AF$1,0))} -> #N/A | J36: 1 | K36: 1 | L36: 8 | M36: 8 | N36: 5P011 | P36: 1440 | U36: =ROUND((K36*P36+Q36*S36)/60+T36,1) -> 24 | V36: 曾云江/黄庆
A37: 1/13 | D37: DD-J10S-06021-107 | E37: 后隔框 | F37: =+VLOOKUP(D37,[1]Sheet1!$D$2:$E$29166,2,0) -> 后隔框 | G37: A-1 | H37: 45 | I37: {=INDEX([2]Sheet1!$F$1:$AF$65808,MATCH(D37&G37&I$1,[2]Sheet1!$B$1:$B$65808&[2]Sheet1!$D$1:$D$65808&[2]Sheet1!$E$1:$E$65808,0),MATCH(H37,[2]Sheet1!$F$1:$AF$1,0))} -> 45/钳钻孔 | J37: 1 | K37: 1 | L37: 8 | M37: 8 | N37: 4P016 | P37: 960 | U37: =ROUND((K37*P37+Q37*S37)/60+T37,1) -> 16 | V37: 曾云江/黄庆
A38: 1/14-1/15 | D38: CB5327120-003R006 | E38: 8270侧隔框 | F38: =+VLOOKUP(D38,[1]Sheet1!$D$2:$E$29166,2,0) -> 8270侧隔框 | G38: F | H38: 75 | I38: {=INDEX([2]Sheet1!$F$1:$AF$65808,MATCH(D38&G38&I$1,[2]Sheet1!$B$1:$B$65808&[2]Sheet1!$D$1:$D$65808&[2]Sheet1!$E$1:$E$65808,0),MATCH(H38,[2]Sheet1!$F$1:$AF$1,0))} -> 75/钳工 | J38: 3 | K38: 3 | L38: 13 | M38: 13 | N38: 5P010-5P011 5P017 | P38: {=IFERROR(INDEX([2]Sheet1!$F$1:$AF$65808,MATCH($D38&$G38&P$1,[2]Sheet1!$B$1:$B$65808&[2]Sheet1!$D$1:$D$65808&[2]Sheet1!$E$1:$E$65808,0),MATCH($H38,[2]Sheet1!$F$1:$AF$1,0)),0)} -> 600 | U38: =ROUND((K38*P38+Q38*S38)/60+T38,1) -> 30 | V38: 曾云江
A39: 1/14-1/15 | D39: CB5327120-003L006 | E39: 8270侧隔框 | F39: =+VLOOKUP(D39,[1]Sheet1!$D$2:$E$29166,2,0) -> 8270侧隔框 | G39: F | H39: 75 | I39: {=INDEX([2]Sheet1!$F$1:$AF$65808,MATCH(D39&G39&I$1,[2]Sheet1!$B$1:$B$65808&[2]Sheet1!$D$1:$D$65808&[2]Sheet1!$E$1:$E$65808,0),MATCH(H39,[2]Sheet1!$F$1:$AF$1,0))} -> 75/钳工 | J39: 3 | K39: 3 | L39: 8 | M39: 8 | N39: 5P010-5P011 5P017 | P39: {=IFERROR(INDEX([2]Sheet1!$F$1:$AF$65808,MATCH($D39&$G39&P$1,[2]Sheet1!$B$1:$B$65808&[2]Sheet1!$D$1:$D$65808&[2]Sheet1!$E$1:$E$65808,0),MATCH($H39,[2]Sheet1!$F$1:$AF$1,0)),0)} -> 600 | U39: =ROUND((K39*P39+Q39*S39)/60+T39,1) -> 30 | V39: 曾云江
A40: 1/14-1/15 | D40: CB5327120-003R006 | E40: 8270侧隔框 | F40: =+VLOOKUP(D40,[1]Sheet1!$D$2:$E$29166,2,0) -> 8270侧隔框 | G40: F | H40: 55 | I40: {=INDEX([2]Sheet1!$F$1:$AF$65808,MATCH(D40&G40&I$1,[2]Sheet1!$B$1:$B$65808&[2]Sheet1!$D$1:$D$65808&[2]Sheet1!$E$1:$E$65808,0),MATCH(H40,[2]Sheet1!$F$1:$AF$1,0))} -> 55/钳工 | J40: 5 | K40: 5 | L40: 30 | M40: 30 | N40: 6P002-6P006 | P40: {=IFERROR(INDEX([2]Sheet1!$F$1:$AF$65808,MATCH($D40&$G40&P$1,[2]Sheet1!$B$1:$B$65808&[2]Sheet1!$D$1:$D$65808&[2]Sheet1!$E$1:$E$65808,0),MATCH($H40,[2]Sheet1!$F$1:$AF$1,0)),0)} -> 120 | U40: =ROUND((K40*P40+Q40*S40)/60+T40,1) -> 10 | V40: 曾云江
...

Sheet 数据源 (整理)
A1: 日 期 | B1: 班次 | C1: 机床号 | D1: 图 号 | E1: 零件名称 | F1: 校对 | G1: 成本核对 | H1: 版次 | I1: 工 序 | J1: 工序内容 | K1: 计划数量 | L1: 完成数量 | M1: 首检 | N1: 批检 | O1: 质量编号 | P1: 输入程序时间 | Q1: 程序时间 | R1: 准备工时 | S1: 输入准备工时 | T1: 调序 | U1: 辅助工时 | V1: 合计 | W1: 操作者 | X1: 备注 | Y1: 负责人签字
A2: 1/3 | D2: CB2284460-007-001 | E2: 四通接头 | F2: 四通接头 | G2: =IFERROR(VLOOKUP(D2,[5]成飞半成品!$A:$B,2,0),VLOOKUP(D2,[5]九院成本!$A$4:$B$48,2,0)) -> 四通接头 | H2: B | I2: 65 | J2: #VALUE! | K2: 8 | L2: 8 | M2: 8 | N2: 8 | O2: 6P001 6P003 | Q2: 35 | V2: 4.7 | W2: 毛波
A3: 1/4 | D3: DD-J10-21102-32-Z | E3: 10460上接头 | F3: 10460上接头 | G3: =IFERROR(VLOOKUP(D3,[5]成飞半成品!$A:$B,2,0),VLOOKUP(D3,[5]九院成本!$A$4:$B$48,2,0)) -> 10060下接头 | H3: D | I3: 40 | J3: 40/钳工 | K3: 2 | L3: 2 | M3: 30 | N3: 30 | O3: C7P007-C7P008 | Q3: 15 | V3: 0.5 | W3: 毛波
A4: 1/5 | D4: CB221T3LG-002-001 | E4: 接头 | F4: 接头 | G4: =IFERROR(VLOOKUP(D4,[5]成飞半成品!$A:$B,2,0),VLOOKUP(D4,[5]九院成本!$A$4:$B$48,2,0)) -> 接头 | H4: B | I4: 10 | J4: 10/钳工 | K4: 5 | L4: 5 | M4: 8 | N4: 8 | O4: 6P001 | Q4: 15 | V4: 1.3 | W4: 毛波 | X4: Q 去毛刺 打钢印 5根料
A5: 1/7 | D5: CB22836Y6-003-001 | E5: 轴 | F5: 轴 | G5: =IFERROR(VLOOKUP(D5,[5]成飞半成品!$A:$B,2,0),VLOOKUP(D5,[5]九院成本!$A$4:$B$48,2,0)) -> 轴 | H5: B | I5: 15 | J5: 15/钳工 | K5: 2 | L5: 2 | M5: 8 | N5: 8 | O5: 1P004 2P004 | Q5: 4 | V5: 0.1 | W5: 毛波
A6: 1/7 | D6: CB2283664-002-001 | E6: 法兰 | F6: 法兰 | G6: =IFERROR(VLOOKUP(D6,[5]成飞半成品!$A:$B,2,0),VLOOKUP(D6,[5]九院成本!$A$4:$B$48,2,0)) -> 法兰 | H6: C | I6: 35 | J6: 35/钳工 | K6: 80 | L6: 80 | M6: 8 | N6: 8 | O6: 6P001 | Q6: 25 | V6: 33.3 | W6: 毛波
A7: 1/8 | D7: DD-J10-21102-32-Y | E7: 10060下接头 | F7: 10060下接头 | G7: =IFERROR(VLOOKUP(D7,[5]成飞半成品!$A:$B,2,0),VLOOKUP(D7,[5]九院成本!$A$4:$B$48,2,0)) -> 10060下接头 | H7: D | I7: 40 | J7: 40/钳工 | K7: 2 | L7: 2 | M7: 30 | N7: 30 | O7: C7P001 C7P002 | Q7: 15 | V7: 0.5 | W7: 毛波
A8: 1/8 | D8: CB5350500-010L006 | E8: 1号护板维型肋左件 | F8: 1号护板维型肋左件 | G8: =IFERROR(VLOOKUP(D8,[5]成飞半成品!$A:$B,2,0),VLOOKUP(D8,[5]九院成本!$A$4:$B$48,2,0)) -> 1号护板维型肋左件 | H8: B | I8: 35 | J8: 35/钳工 | K8: 23 | L8: 23 | M8: 8 | N8: 8 | O8: 6P001 | Q8: 45 | V8: 17.3 | W8: 毛波
A9: 1/9 | D9: CB2747GA0-002-002 | E9: 扩压式管接头 | F9: 扩压式管接头 | G9: =IFERROR(VLOOKUP(D9,[5]成飞半成品!$A:$B,2,0),VLOOKUP(D9,[5]九院成本!$A$4:$B$48,2,0)) -> 扩压式管接头 | H9: C | I9: 45 | J9: 45/钳工 | K9: 30 | L9: 30 | M9: 8 | N9: 8 | O9: 6P001 | Q9: 40 | V9: 20 | W9: 毛波
A10: 1/11 | D10: DD-J10B-94076-2031/3 | E10: 接管嘴 | F10: 接管嘴 | G10: =IFERROR(VLOOKUP(D10,[5]成飞半成品!$A:$B,2,0),VLOOKUP(D10,[5]九院成本!$A$4:$B$48,2,0)) -> 接管嘴 | H10: B | I10: 35 | J10: 35/钳工 | K10: 29 | L10: 29 | M10: 8 | N10: 8 | O10: 6P003 6P005 | Q10: 35 | V10: 16.9 | W10: 毛波
A11: 1/11 | D11: 5317C23409G70 | E11: 立柱加强接头 | F11: 立柱加强接头 | G11: =IFERROR(VLOOKUP(D11,[5]成飞半成品!$A:$B,2,0),VLOOKUP(D11,[5]九院成本!$A$4:$B$48,2,0)) -> 立柱加强接头 | H11: A | I11: 35 | J11: 35钳工 | K11: 9 | L11: 9 | M11: 8 | N11: 8 | O11: 3A | Q11: 50 | V11: 7.5 | W11: 毛波
A12: 1/12 | D12: DD-J10B-94076-501-Z | E12: 拉杆支座 | F12: 拉杆支座 | G12: =IFERROR(VLOOKUP(D12,[5]成飞半成品!$A:$B,2,0),VLOOKUP(D12,[5]九院成本!$A$4:$B$48,2,0)) -> 拉杆支座 | H12: B | I12: 80 | J12: 80/检验 | K12: 12 | L12: 12 | M12: 8 | N12: 8 | O12: 6P005 | Q12: 0 | V12: 0 | W12: 毛波
A13: 1/12 | D13: DD-J10B-61041-18 | E13: 管接头 | F13: 管接头 | G13: =IFERROR(VLOOKUP(D13,[5]成飞半成品!$A:$B,2,0),VLOOKUP(D13,[5]九院成本!$A$4:$B$48,2,0)) -> 管接头 | H13: C | I13: 35 | J13: 35/钳工 | K13: 60 | L13: 60 | M13: 8 | N13: 8 | O13: 6P004 | Q13: 30 | V13: 30 | W13: 毛波
A14: 1/13 | D14: CB5811100-010-001 | E14: 螺栓 | F14: 螺栓 | G14: =IFERROR(VLOOKUP(D14,[5]成飞半成品!$A:$B,2,0),VLOOKUP(D14,[5]九院成本!$A$4:$B$48,2,0)) -> 螺栓 | H14: C | I14: 50 | J14: 50/钳工 | K14: 20 | L14: 20 | M14: 8 | N14: 8 | O14: 6P001 | Q14: 25 | V14: 8.3 | W14: 毛波
A15: 1/13 | D15: C256300800-003-001 | E15: 垫圈 | F15: 垫圈 | G15: =IFERROR(VLOOKUP(D15,[5]成飞半成品!$A:$B,2,0),VLOOKUP(D15,[5]九院成本!$A$4:$B$48,2,0)) -> 垫圈 | H15: A | I15: 10 | J15: 10钳工 | K15: 2 | L15: 2 | M15: 8 | N15: 8 | O15: 00P001 | Q15: 4 | V15: 0.1 | W15: 毛波 | X15: D 打钢印 2根料
A16: 1/13 | D16: 5319C96017G70 | E16: 短框连接块 | F16: 短框连接块 | G16: =IFERROR(VLOOKUP(D16,[5]成飞半成品!$A:$B,2,0),VLOOKUP(D16,[5]九院成本!$A$4:$B$48,2,0)) -> 短框连接块 | H16: A | I16: 30 | J16: 30/钳工 | K16: 8 | L16: 8 | M16: 8 | N16: 8 | O16: 3A | Q16: 50 | V16: 6.7 | W16: 毛波
A17: 1/13 | D17: DD-J10-21102-32-Y | E17: 10060下接头 | F17: 10060下接头 | G17: =IFERROR(VLOOKUP(D17,[5]成飞半成品!$A:$B,2,0),VLOOKUP(D17,[5]九院成本!$A$4:$B$48,2,0)) -> 10060下接头 | H17: D | I17: 40 | J17: 40/钳工 | K17: 6 | L17: 6 | M17: 30 | N17: 30 | O17: C7P003-C7P008 | Q17: 15 | V17: 1.5 | W17: 毛波
A18: 1/14 | D18: DD-J10-61101-5001/16 | E18: 管接头 | F18: 管接头 | G18: =IFERROR(VLOOKUP(D18,[5]成飞半成品!$A:$B,2,0),VLOOKUP(D18,[5]九院成本!$A$4:$B$48,2,0)) -> 管接头 | H18: C | I18: 35 | J18: 35/钳工 | K18: 20 | L18: 20 | M18: 8 | N18: 8 | O18: C6P004 | Q18: 30 | V18: 10 | W18: 毛波
A19: 1/15 | D19: DD-J10-61052-172 | E19: 接管嘴 | F19: 接管嘴 | G19: =IFERROR(VLOOKUP(D19,[5]成飞半成品!$A:$B,2,0),VLOOKUP(D19,[5]九院成本!$A$4:$B$48,2,0)) -> 接管嘴 | H19: B | I19: 30 | J19: 30/钳工 | K19: 60 | L19: 60 | M19: 8 | N19: 8 | O19: C6P005 | Q19: 25 | V19: 25 | W19: 毛波
A20: 1/15 | D20: C221069811-001-001 | E20: 平管嘴 | F20: 平管嘴 | G20: =IFERROR(VLOOKUP(D20,[5]成飞半成品!$A:$B,2,0),VLOOKUP(D20,[5]九院成本!$A$4:$B$48,2,0)) -> 平管嘴 | H20: A | I20: 10 | J20: 10钳工 | K20: 14 | L20: 14 | M20: 8 | N20: 8 | O20: 00P001 00P002 | Q20: 4 | V20: 0.9 | W20: 毛波
A21: 1/16 | D21: CB5811100-010-001 | E21: 螺栓 | F21: 螺栓 | G21: =IFERROR(VLOOKUP(D21,[5]成飞半成品!$A:$B,2,0),VLOOKUP(D21,[5]九院成本!$A$4:$B$48,2,0)) -> 螺栓 | H21: C | I21: 70 | J21: 0 | K21: 20 | L21: 20 | M21: 8 | N21: 8 | O21: 6P001 | Q21: 0 | V21: 0 | W21: 毛波
A22: 1/16 | D22: CB221T2LN-001-001 | E22: 接管嘴 | F22: 接管嘴 | G22: =IFERROR(VLOOKUP(D22,[5]成飞半成品!$A:$B,2,0),VLOOKUP(D22,[5]九院成本!$A$4:$B$48,2,0)) -> 接管嘴 | H22: B | I22: 35 | J22: 35/钳工 | K22: 19 | L22: 19 | M22: 8 | N22: 8 | O22: 6P001 | Q22: 15 | V22: 4.8 | W22: 毛波
A23: 1/16 | D23: BC221T1BB-001-001 | E23: 法兰 | F23: 法兰 | G23: =IFERROR(VLOOKUP(D23,[5]成飞半成品!$A:$B,2,0),VLOOKUP(D23,[5]九院成本!$A$4:$B$48,2,0)) -> 法兰 | H23: C | I23: 50 | J23: 50/钳工 | K23: 2 | L23: 2 | M23: 8 | N23: 8 | O23: 2P004 | Q23: 50 | V23: 1.7 | W23: 毛波
A24: 1/16 | D24: DD-J10B-61201-12 | E24: 接头 | F24: 接头 | G24: =IFERROR(VLOOKUP(D24,[5]成飞半成品!$A:$B,2,0),VLOOKUP(D24,[5]九院成本!$A$4:$B$48,2,0)) -> 接头 | H24: E | I24: 35 | J24: 35/钳工 | K24: 21 | L24: 21 | M24: 8 | N24: 8 | O24: 7P003 | Q24: 20 | V24: 7 | W24: 毛波
A25: 1/18 | D25: DD-J10B-94091-24G2 | E25: 20-28变径直通接头 | F25: 20-28变径直通接头 | G25: =IFERROR(VLOOKUP(D25,[5]成飞半成品!$A:$B,2,0),VLOOKUP(D25,[5]九院成本!$A$4:$B$48,2,0)) -> 20-28变径直通接头 | H25: B | I25: 10 | J25: 10/钳毛刺 | K25: 20 | L25: 20 | M25: 8 | N25: 8 | O25: 6P004 | Q25: 10 | V25: 3.3 | W25: 毛波
A26: 1/18 | D26: 5319C22035G70 | E26: 支架 | F26: 支架 | G26: =IFERROR(VLOOKUP(D26,[5]成飞半成品!$A:$B,2,0),VLOOKUP(D26,[5]九院成本!$A$4:$B$48,2,0)) -> 支架 | H26: A | I26: 25 | J26: 25钳工 | K26: 4 | L26: 4 | M26: 8 | N26: 8 | O26: 3A | Q26: 45 | V26: 3 | W26: 毛波
A27: 1/3 | D27: CB5323210-005L065 | E27: 9350-11140左侧上梁 | F27: 9350-11140左侧上梁 | G27: =IFERROR(VLOOKUP(D27,[5]成飞半成品!$A:$B,2,0),VLOOKUP(D27,[5]九院成本!$A$4:$B$48,2,0)) -> 9350-11140左侧上梁 | H27: C | I27: 40 | J27: #N/A | K27: 4 | L27: 4 | M27: 8 | N27: 8 | O27: 5P009 5P011 5P013 5P020 | Q27: 1440 | V27: 96 | W27: 曾云江/黄庆
A28: 1/4 | D28: 2020-10-N-75 | E28: XXXXXXX离心夹具3组合件 | F28: XXXXXXX离心夹具3组合件 | G28: =IFERROR(VLOOKUP(D28,[5]成飞半成品!$A:$B,2,0),VLOOKUP(D28,[5]九院成本!$A$4:$B$48,2,0)) -> 1N-2020-10-025 | H28: A | I28: 8 | J28: #N/A | K28: 2 | L28: 2 | M28: 8 | N28: 8 | O28: 2020-10-N-75 | Q28: 60 | V28: 2 | W28: 曾云江
A29: 1/5 | D29: CB5327110-003R002 | E29: 8635右隔框 | F29: 8635右隔框 | G29: =IFERROR(VLOOKUP(D29,[5]成飞半成品!$A:$B,2,0),VLOOKUP(D29,[5]九院成本!$A$4:$B$48,2,0)) -> 8635右隔框 | H29: E | I29: 35 | J29: 35/钳工 | K29: 3 | L29: 3 | M29: 8 | N29: 8 | O29: 5P008 5P017-5P018 | Q29: 120 | V29: 6 | W29: 曾云江
A30: 1/5 | D30: 工装 | E30: 后隔框 | F30: 后隔框 | G30: =IFERROR(VLOOKUP(D30,[5]成飞半成品!$A:$B,2,0),VLOOKUP(D30,[5]九院成本!$A$4:$B$48,2,0)) -> 工装 | H30: A-1 | I30: 45 | J30: 45/钳钻孔 | K30: 1 | L30: 1 | M30: 8 | N30: 8 | O30: 4P015 | Q30: 960 | V30: 16 | W30: 曾云江/黄庆
A31: 1/5 | D31: =O31 -> 2020-07-N-67 | E31: D 导向块 | F31: 密封圈3 | G31: =IFERROR(VLOOKUP(D31,[5]成飞半成品!$A:$B,2,0),VLOOKUP(D31,[5]九院成本!$A$4:$B$48,2,0)) -> 1N-2020-06-067 | I31: 35 | J31: #N/A | K31: 2300 | L31: 1200 | M31: 8 | N31: 8 | O31: 2020-07-N-67 | Q31: 15 | V31: 300 | W31: 曾云江
A32: 1/8 | D32: CB5327110-003L002 | E32: 8635左隔框 | F32: 8635左隔框 | G32: =IFERROR(VLOOKUP(D32,[5]成飞半成品!$A:$B,2,0),VLOOKUP(D32,[5]九院成本!$A$4:$B$48,2,0)) -> 8635左隔框 | H32: E | I32: 35 | J32: 35/钳工 | K32: 3 | L32: 3 | M32: 8 | N32: 8 | O32: 5P002 5P016 5P018 | Q32: 120 | V32: 6 | W32: 曾云江
A33: 1/8 | D33: CB5327110-003R002 | E33: 8635右隔框 | F33: 8635右隔框 | G33: =IFERROR(VLOOKUP(D33,[5]成飞半成品!$A:$B,2,0),VLOOKUP(D33,[5]九院成本!$A$4:$B$48,2,0)) -> 8635右隔框 | H33: E | I33: 45 | J33: 45/钳工 | K33: 3 | L33: 3 | M33: 30 | N33: 30 | O33: 5P008 5P017-5P018 | Q33: 480 | V33: 24 | W33: 曾云江
A34: 1/9 | D34: CB5327110-003L002 | E34: 8635左隔框 | F34: 8635左隔框 | G34: =IFERROR(VLOOKUP(D34,[5]成飞半成品!$A:$B,2,0),VLOOKUP(D34,[5]九院成本!$A$4:$B$48,2,0)) -> 8635左隔框 | H34: E | I34: 45 | J34: 45/钳工 | K34: 3 | L34: 3 | M34: 30 | N34: 30 | O34: 5P002 5P016 5P018 | Q34: 480 | V34: 24 | W34: 曾云江
A35: 1/9 | D35: CB5323210-005L065 | E35: 9350-11140左侧上梁 | F35: 9350-11140左侧上梁 | G35: =IFERROR(VLOOKUP(D35,[5]成飞半成品!$A:$B,2,0),VLOOKUP(D35,[5]九院成本!$A$4:$B$48,2,0)) -> 9350-11140左侧上梁 | H35: C | I35: 50 | J35: #N/A | K35: 1 | L35: 1 | M35: 8 | N35: 8 | O35: 5P009 | Q35: 1440 | V35: 24 | W35: 曾云江/黄庆
A36: 1/12 | D36: CB5323210-005L065 | E36: 9350-11140左侧上梁 | F36: 9350-11140左侧上梁 | G36: =IFERROR(VLOOKUP(D36,[5]成飞半成品!$A:$B,2,0),VLOOKUP(D36,[5]九院成本!$A$4:$B$48,2,0)) -> 9350-11140左侧上梁 | H36: C | I36: 50 | J36: #N/A | K36: 1 | L36: 1 | M36: 8 | N36: 8 | O36: 5P011 | Q36: 1440 | V36: 24 | W36: 曾云江/黄庆
A37: 1/13 | D37: 工装 | E37: 后隔框 | F37: 后隔框 | G37: =IFERROR(VLOOKUP(D37,[5]成飞半成品!$A:$B,2,0),VLOOKUP(D37,[5]九院成本!$A$4:$B$48,2,0)) -> 工装 | H37: A-1 | I37: 45 | J37: 45/钳钻孔 | K37: 1 | L37: 1 | M37: 8 | N37: 8 | O37: 4P016 | Q37: 960 | V37: 16 | W37: 曾云江/黄庆
A38: 1/14-1/15 | D38: CB5327110-002L002 | E38: 8270侧隔框 | F38: 8270侧隔框 | G38: =IFERROR(VLOOKUP(D38,[5]成飞半成品!$A:$B,2,0),VLOOKUP(D38,[5]九院成本!$A$4:$B$48,2,0)) -> 8270左隔框 | H38: F | I38: 75 | J38: 75/钳工 | K38: 3 | L38: 3 | M38: 13 | N38: 13 | O38: 5P010-5P011 5P017 | Q38: 600 | V38: 30 | W38: 曾云江
A39: 1/14-1/15 | D39: CB5327110-002L002 | E39: 8270侧隔框 | F39: 8270侧隔框 | G39: =IFERROR(VLOOKUP(D39,[5]成飞半成品!$A:$B,2,0),VLOOKUP(D39,[5]九院成本!$A$4:$B$48,2,0)) -> 8270左隔框 | H39: F | I39: 75 | J39: 75/钳工 | K39: 3 | L39: 3 | M39: 8 | N39: 8 | O39: 5P010-5P011 5P017 | Q39: 600 | V39: 30 | W39: 曾云江
A40: 1/14-1/15 | D40: CB5327110-002R002 | E40: 8270侧隔框 | F40: 8270侧隔框 | G40: =IFERROR(VLOOKUP(D40,[5]成飞半成品!$A:$B,2,0),VLOOKUP(D40,[5]九院成本!$A$4:$B$48,2,0)) -> 8270右隔框 | H40: F | I40: 55 | J40: 55/钳工 | K40: 5 | L40: 5 | M40: 30 | N40: 30 | O40: 6P002-6P006 | Q40: 120 | V40: 10 | W40: 曾云江
...

Sheet Sheet2
A3: 机床号 | B3: 图 号 | C3: 零件名称 | D3: 数量 | E3: 工时 | F3: 占比 | G3: 费用分摊
B4: 2020-01-N-03 | D4: 40 | E4: 6.7 | F4: 0.00059945602
B5: 2020-01-N-12 | D5: 3380 | E5: 169 | F5: 0.015120607
B6: 2020-04-N-39 | D6: 40 | E6: 20 | F6: 0.0017894209
B7: 2020-07-N-67 | D7: 4700 | E7: 475 | F7: 0.042498747
B8: 2020-10-N-35 | D8: 5349 | E8: 640.7 | F8: 0.0573241
B9: 2020-10-N-75 | D9: 14 | E9: 231.7 | F9: 0.020730442
B10: 2020-11-N-21 | D10: 636 | E10: 186 | F10: 0.016641615
B11: 2020-12-N-01 | D11: 446 | E11: 38.7 | F11: 0.0034625295
B12: 2020-12-N-04 | D12: 471 | E12: 91.4 | F12: 0.0081776537
B13: 2020-12-N-10 | D13: 358 | E13: 28.3 | F13: 0.0025320306
B14: 2710A400004G010 | D14: 10 | E14: 1 | F14: 8.9471047e-05
B15: 3D | D15: 4 | E15: 12 | F15: 0.0010736526
... B305: 总计 | D305: 28159 | E305: 11176.8 | F305: 1
