Workbook

Sheet 使用说明
B1: 烨软科技 盈亏平衡测算模型
B2: —— 两个产品（120 / 155）要卖多少才不亏钱？
B4: 怎么用？三步
B5: 第一步：点「产品参数」
B6: 黄色格子改销量。白色格子自动算，改完回车利润自动刷新。
B7: 第二步：点「盈亏平衡计算」
B8: 5 BEP收入 = 保本线 7 安全边际 = 比保本线多多少（负=亏） 盈亏状态 = 赚/亏
B9: 第三步：点「可视化」
B10: 图A 收入vs成本交叉点 = 保本位置 图B 利润曲线 = 啥时候开始赚钱 图C 等利润线 = 两个产品怎么搭才保本，红圈=你现在在哪
B12: 当前结果（数据来源于你填的参数）
B13: 公司一年固定开销： | C13: 349 万 工资+房租+利息等，详见「盈亏平衡计算」
B14: 贸易业务贡献： | C14: 60 万 固定利润，不参与本表计算
B15: 120和155需赚回： | C15: 289 万 349-60，这是两个产品要拼的
B16: 保本需要卖到： | C16: 525 万 120+155合计收入
B17: 现在实际卖： | C17: 330 万 假设各卖500个，去「产品参数」改
B18: 当前结果： | C18: 亏 107 万 差 195 万才保本
B20: 快速算：想赚多少钱，得卖多少？
B21: 公式：(289万 + 想要的利润) / 55% = 需要卖到
B22: 不亏（保本）：需要卖到 525 万
B23: 赚 50 万：需要卖到 616 万
B24: 赚 100 万：需要卖到 707 万
B26: 注意事项
B27: · 只改黄色格子，其他格子有公式，改了就坏了
B28: · 毛利率会自动根据你填的单价/成本算，不用手填
B29: · 利息按当前贷款算（1.5万/月），还了贷款要改月利息
B30: · 折旧 30 万/年是非现金支出，现金流比报表利润好看

Sheet 产品参数
A1: 烨软科技 盈亏平衡测算模型
A2: 黄色 = 手动改 白色 = 公式自动
A4: 一、产品参数
B5: 120 | C5: 155 | D5: 研发产品 | E5: 贸易
A6: 年销量（个） | B6: 500 | C6: 500 | D6: 1 | E6: 1
A7: 单价（元） | B7: 2600 | C7: 4000 | D7: 1000000 | E7: 3000000
A8: 单位材料成本（元） | B8: 1170 | C8: 1800 | D8: 1000000 | E8: 2400000
A10: 单位毛利（元） | B10: =B7-B8 | C10: =C7-C8 | D10: =D7-D8 | E10: =E7-E8
A11: 毛利率 | B11: =IF(B7=0,"-",B10/B7) | C11: =IF(C7=0,"-",C10/C7) | D11: =IF(D7=0,"-",D10/D7) | E11: =IF(E7=0,"-",E10/E7)
A13: 年收入 | B13: =B6*B7 | C13: =C6*C7 | D13: =D6*D7 | E13: =E6*E7
A14: 年毛利额 | B14: =B10*B6 | C14: =C10*C6 | D14: =D10*D6 | E14: =E10*E6
A16: 二、汇总
A17: 总收入 | B17: =SUM(B13:E13)
A18: 总毛利 | B18: =SUM(B14:E14)
A19: 综合毛利率 | B19: =IF(B17=0,"-",B18/B17)
A20: 120&155 合计收入 | B20: =B13+C13
A21: 120&155 毛利率 | B21: =IF(B20=0,"-",(B14+C14)/B20)
A23: 三、利润快算
A24: 总毛利 | B24: =B18
A25: 固定费用 | B25: ='盈亏平衡计算'!C13
A26: 利润 | B26: =B24-B25

Sheet 盈亏平衡计算
A1: 盈亏平衡计算
A3: 一、固定费用明细（年）
A4: 项目 | B4: 月（可调） | C4: 年（=月x12）
A5: 人工（含社保） | B5: 230000 | C5: =B5*12
A6: 房租 | B6: 14036 | C6: =B6*12
A7: 水电 | B7: 1500 | C7: =B7*12
A8: 物管 | B8: 1750 | C8: =B8*12
A9: 折旧 | B9: 25000 | C9: =B9*12
A10: 办公费 | B10: 2000 | C10: =B10*12
A11: 中介费 | B11: 1500 | C11: =B11*12
A12: 利息 | B12: 15000 | C12: =B12*12
A13: 固定费用合计 | B13: - | C13: =SUM(C5:C12)
A15: 二、盈亏平衡计算
A16: 1 固定费用合计 | B16: =C13
A17: 2 贸易年毛利（=产品参数!E列年毛利额） | B17: ='产品参数'!E14
A18: 3 = 1 - 2 需120&155弥补的毛利缺口 | B18: =B16-B17
A19: 4 120&155 毛利率（=产品参数!B21） | B19: ='产品参数'!B21
A20: 5 = 3 / 4 BEP收入（120&155需达到） | B20: =IF(B19=0,"-",B18/B19)
A22: 6 当前120&155实际收入（=产品参数!B20） | B22: ='产品参数'!B20
A23: 7 = 6 - 5 安全边际（金额） | B23: =B22-B20
A24: 8 = 7 / 6 安全边际率 | B24: =IF(B22=0,"-",B23/B22)
A26: -> 盈亏状态 | B26: =IF(B23>=0,"[ 盈 利 ]","[ 亏 损 ]")
A28: 三、BEP组合分解（任意组合，120/155收入合计>=BEP收入即可保本）
A29: 情景 | B29: 120年销量 | C29: 155年销量 | D29: 120收入 | E29: 155收入 | F29: 120&155合计 | G29: 是否保本
A30: 纯卖120 | B30: =ROUNDUP(B20/'产品参数'!B7,0) | C30: 0 | D30: =B30*'产品参数'!B7 | E30: 0 | F30: =D30+E30 | G30: =IF(F30>=B20,"OK 保本","X 亏损")
A31: 纯卖155 | B31: 0 | C31: =ROUNDUP(B20/'产品参数'!C7,0) | D31: 0 | E31: =C31*'产品参数'!C7 | F31: =D31+E31 | G31: =IF(F31>=B20,"OK 保本","X 亏损")
A32: 当前组合 | B32: ='产品参数'!B6 | C32: ='产品参数'!C6 | D32: =B32*'产品参数'!B7 | E32: =C32*'产品参数'!C7 | F32: =D32+E32 | G32: =IF(F32>=B20,"OK 保本","X 亏损")
A34: 四、当前利润
A35: 总毛利（=产品参数!B18） | B35: ='产品参数'!B18
A36: 固定费用（=上面合计） | B36: =C13
A37: 利润 | B37: =B35-B36

Sheet 敏感性分析
A1: 产品组合敏感性分析（利润矩阵）
A2: 行=120年销量 列=155年销量 格=利润(元) 绿盈红亏 (公式联动，改参数自动刷新)
A4: 120 / 155 -> | B4: 0 | C4: 200 | D4: 400 | E4: 600 | F4: 800 | G4: 1000 | H4: 1200 | I4: 1400 | J4: 1600 | K4: 1800 | L4: 2000
A5: 0 | B5: =A5*'产品参数'!B10+B$4*'产品参数'!C10+'产品参数'!E14-'盈亏平衡计算'!C13 | C5: =A5*'产品参数'!B10+C$4*'产品参数'!C10+'产品参数'!E14-'盈亏平衡计算'!C13 | D5: =A5*'产品参数'!B10+D$4*'产品参数'!C10+'产品参数'!E14-'盈亏平衡计算'!C13 | E5: =A5*'产品参数'!B10+E$4*'产品参数'!C10+'产品参数'!E14-'盈亏平衡计算'!C13 | F5: =A5*'产品参数'!B10+F$4*'产品参数'!C10+'产品参数'!E14-'盈亏平衡计算'!C13 | G5: =A5*'产品参数'!B10+G$4*'产品参数'!C10+'产品参数'!E14-'盈亏平衡计算'!C13 | H5: =A5*'产品参数'!B10+H$4*'产品参数'!C10+'产品参数'!E14-'盈亏平衡计算'!C13 | I5: =A5*'产品参数'!B10+I$4*'产品参数'!C10+'产品参数'!E14-'盈亏平衡计算'!C13 | J5: =A5*'产品参数'!B10+J$4*'产品参数'!C10+'产品参数'!E14-'盈亏平衡计算'!C13 | K5: =A5*'产品参数'!B10+K$4*'产品参数'!C10+'产品参数'!E14-'盈亏平衡计算'!C13 | L5: =A5*'产品参数'!B10+L$4*'产品参数'!C10+'产品参数'!E14-'盈亏平衡计算'!C13
A6: 250 | B6: =A6*'产品参数'!B10+B$4*'产品参数'!C10+'产品参数'!E14-'盈亏平衡计算'!C13 | C6: =A6*'产品参数'!B10+C$4*'产品参数'!C10+'产品参数'!E14-'盈亏平衡计算'!C13 | D6: =A6*'产品参数'!B10+D$4*'产品参数'!C10+'产品参数'!E14-'盈亏平衡计算'!C13 | E6: =A6*'产品参数'!B10+E$4*'产品参数'!C10+'产品参数'!E14-'盈亏平衡计算'!C13 | F6: =A6*'产品参数'!B10+F$4*'产品参数'!C10+'产品参数'!E14-'盈亏平衡计算'!C13 | G6: =A6*'产品参数'!B10+G$4*'产品参数'!C10+'产品参数'!E14-'盈亏平衡计算'!C13 | H6: =A6*'产品参数'!B10+H$4*'产品参数'!C10+'产品参数'!E14-'盈亏平衡计算'!C13 | I6: =A6*'产品参数'!B10+I$4*'产品参数'!C10+'产品参数'!E14-'盈亏平衡计算'!C13 | J6: =A6*'产品参数'!B10+J$4*'产品参数'!C10+'产品参数'!E14-'盈亏平衡计算'!C13 | K6: =A6*'产品参数'!B10+K$4*'产品参数'!C10+'产品参数'!E14-'盈亏平衡计算'!C13 | L6: =A6*'产品参数'!B10+L$4*'产品参数'!C10+'产品参数'!E14-'盈亏平衡计算'!C13
A7: 500 | B7: =A7*'产品参数'!B10+B$4*'产品参数'!C10+'产品参数'!E14-'盈亏平衡计算'!C13 | C7: =A7*'产品参数'!B10+C$4*'产品参数'!C10+'产品参数'!E14-'盈亏平衡计算'!C13 | D7: =A7*'产品参数'!B10+D$4*'产品参数'!C10+'产品参数'!E14-'盈亏平衡计算'!C13 | E7: =A7*'产品参数'!B10+E$4*'产品参数'!C10+'产品参数'!E14-'盈亏平衡计算'!C13 | F7: =A7*'产品参数'!B10+F$4*'产品参数'!C10+'产品参数'!E14-'盈亏平衡计算'!C13 | G7: =A7*'产品参数'!B10+G$4*'产品参数'!C10+'产品参数'!E14-'盈亏平衡计算'!C13 | H7: =A7*'产品参数'!B10+H$4*'产品参数'!C10+'产品参数'!E14-'盈亏平衡计算'!C13 | I7: =A7*'产品参数'!B10+I$4*'产品参数'!C10+'产品参数'!E14-'盈亏平衡计算'!C13 | J7: =A7*'产品参数'!B10+J$4*'产品参数'!C10+'产品参数'!E14-'盈亏平衡计算'!C13 | K7: =A7*'产品参数'!B10+K$4*'产品参数'!C10+'产品参数'!E14-'盈亏平衡计算'!C13 | L7: =A7*'产品参数'!B10+L$4*'产品参数'!C10+'产品参数'!E14-'盈亏平衡计算'!C13
A8: 750 | B8: =A8*'产品参数'!B10+B$4*'产品参数'!C10+'产品参数'!E14-'盈亏平衡计算'!C13 | C8: =A8*'产品参数'!B10+C$4*'产品参数'!C10+'产品参数'!E14-'盈亏平衡计算'!C13 | D8: =A8*'产品参数'!B10+D$4*'产品参数'!C10+'产品参数'!E14-'盈亏平衡计算'!C13 | E8: =A8*'产品参数'!B10+E$4*'产品参数'!C10+'产品参数'!E14-'盈亏平衡计算'!C13 | F8: =A8*'产品参数'!B10+F$4*'产品参数'!C10+'产品参数'!E14-'盈亏平衡计算'!C13 | G8: =A8*'产品参数'!B10+G$4*'产品参数'!C10+'产品参数'!E14-'盈亏平衡计算'!C13 | H8: =A8*'产品参数'!B10+H$4*'产品参数'!C10+'产品参数'!E14-'盈亏平衡计算'!C13 | I8: =A8*'产品参数'!B10+I$4*'产品参数'!C10+'产品参数'!E14-'盈亏平衡计算'!C13 | J8: =A8*'产品参数'!B10+J$4*'产品参数'!C10+'产品参数'!E14-'盈亏平衡计算'!C13 | K8: =A8*'产品参数'!B10+K$4*'产品参数'!C10+'产品参数'!E14-'盈亏平衡计算'!C13 | L8: =A8*'产品参数'!B10+L$4*'产品参数'!C10+'产品参数'!E14-'盈亏平衡计算'!C13
A9: 1000 | B9: =A9*'产品参数'!B10+B$4*'产品参数'!C10+'产品参数'!E14-'盈亏平衡计算'!C13 | C9: =A9*'产品参数'!B10+C$4*'产品参数'!C10+'产品参数'!E14-'盈亏平衡计算'!C13 | D9: =A9*'产品参数'!B10+D$4*'产品参数'!C10+'产品参数'!E14-'盈亏平衡计算'!C13 | E9: =A9*'产品参数'!B10+E$4*'产品参数'!C10+'产品参数'!E14-'盈亏平衡计算'!C13 | F9: =A9*'产品参数'!B10+F$4*'产品参数'!C10+'产品参数'!E14-'盈亏平衡计算'!C13 | G9: =A9*'产品参数'!B10+G$4*'产品参数'!C10+'产品参数'!E14-'盈亏平衡计算'!C13 | H9: =A9*'产品参数'!B10+H$4*'产品参数'!C10+'产品参数'!E14-'盈亏平衡计算'!C13 | I9: =A9*'产品参数'!B10+I$4*'产品参数'!C10+'产品参数'!E14-'盈亏平衡计算'!C13 | J9: =A9*'产品参数'!B10+J$4*'产品参数'!C10+'产品参数'!E14-'盈亏平衡计算'!C13 | K9: =A9*'产品参数'!B10+K$4*'产品参数'!C10+'产品参数'!E14-'盈亏平衡计算'!C13 | L9: =A9*'产品参数'!B10+L$4*'产品参数'!C10+'产品参数'!E14-'盈亏平衡计算'!C13
A10: 1250 | B10: =A10*'产品参数'!B10+B$4*'产品参数'!C10+'产品参数'!E14-'盈亏平衡计算'!C13 | C10: =A10*'产品参数'!B10+C$4*'产品参数'!C10+'产品参数'!E14-'盈亏平衡计算'!C13 | D10: =A10*'产品参数'!B10+D$4*'产品参数'!C10+'产品参数'!E14-'盈亏平衡计算'!C13 | E10: =A10*'产品参数'!B10+E$4*'产品参数'!C10+'产品参数'!E14-'盈亏平衡计算'!C13 | F10: =A10*'产品参数'!B10+F$4*'产品参数'!C10+'产品参数'!E14-'盈亏平衡计算'!C13 | G10: =A10*'产品参数'!B10+G$4*'产品参数'!C10+'产品参数'!E14-'盈亏平衡计算'!C13 | H10: =A10*'产品参数'!B10+H$4*'产品参数'!C10+'产品参数'!E14-'盈亏平衡计算'!C13 | I10: =A10*'产品参数'!B10+I$4*'产品参数'!C10+'产品参数'!E14-'盈亏平衡计算'!C13 | J10: =A10*'产品参数'!B10+J$4*'产品参数'!C10+'产品参数'!E14-'盈亏平衡计算'!C13 | K10: =A10*'产品参数'!B10+K$4*'产品参数'!C10+'产品参数'!E14-'盈亏平衡计算'!C13 | L10: =A10*'产品参数'!B10+L$4*'产品参数'!C10+'产品参数'!E14-'盈亏平衡计算'!C13
A11: 1500 | B11: =A11*'产品参数'!B10+B$4*'产品参数'!C10+'产品参数'!E14-'盈亏平衡计算'!C13 | C11: =A11*'产品参数'!B10+C$4*'产品参数'!C10+'产品参数'!E14-'盈亏平衡计算'!C13 | D11: =A11*'产品参数'!B10+D$4*'产品参数'!C10+'产品参数'!E14-'盈亏平衡计算'!C13 | E11: =A11*'产品参数'!B10+E$4*'产品参数'!C10+'产品参数'!E14-'盈亏平衡计算'!C13 | F11: =A11*'产品参数'!B10+F$4*'产品参数'!C10+'产品参数'!E14-'盈亏平衡计算'!C13 | G11: =A11*'产品参数'!B10+G$4*'产品参数'!C10+'产品参数'!E14-'盈亏平衡计算'!C13 | H11: =A11*'产品参数'!B10+H$4*'产品参数'!C10+'产品参数'!E14-'盈亏平衡计算'!C13 | I11: =A11*'产品参数'!B10+I$4*'产品参数'!C10+'产品参数'!E14-'盈亏平衡计算'!C13 | J11: =A11*'产品参数'!B10+J$4*'产品参数'!C10+'产品参数'!E14-'盈亏平衡计算'!C13 | K11: =A11*'产品参数'!B10+K$4*'产品参数'!C10+'产品参数'!E14-'盈亏平衡计算'!C13 | L11: =A11*'产品参数'!B10+L$4*'产品参数'!C10+'产品参数'!E14-'盈亏平衡计算'!C13
A12: 1750 | B12: =A12*'产品参数'!B10+B$4*'产品参数'!C10+'产品参数'!E14-'盈亏平衡计算'!C13 | C12: =A12*'产品参数'!B10+C$4*'产品参数'!C10+'产品参数'!E14-'盈亏平衡计算'!C13 | D12: =A12*'产品参数'!B10+D$4*'产品参数'!C10+'产品参数'!E14-'盈亏平衡计算'!C13 | E12: =A12*'产品参数'!B10+E$4*'产品参数'!C10+'产品参数'!E14-'盈亏平衡计算'!C13 | F12: =A12*'产品参数'!B10+F$4*'产品参数'!C10+'产品参数'!E14-'盈亏平衡计算'!C13 | G12: =A12*'产品参数'!B10+G$4*'产品参数'!C10+'产品参数'!E14-'盈亏平衡计算'!C13 | H12: =A12*'产品参数'!B10+H$4*'产品参数'!C10+'产品参数'!E14-'盈亏平衡计算'!C13 | I12: =A12*'产品参数'!B10+I$4*'产品参数'!C10+'产品参数'!E14-'盈亏平衡计算'!C13 | J12: =A12*'产品参数'!B10+J$4*'产品参数'!C10+'产品参数'!E14-'盈亏平衡计算'!C13 | K12: =A12*'产品参数'!B10+K$4*'产品参数'!C10+'产品参数'!E14-'盈亏平衡计算'!C13 | L12: =A12*'产品参数'!B10+L$4*'产品参数'!C10+'产品参数'!E14-'盈亏平衡计算'!C13
A13: 2000 | B13: =A13*'产品参数'!B10+B$4*'产品参数'!C10+'产品参数'!E14-'盈亏平衡计算'!C13 | C13: =A13*'产品参数'!B10+C$4*'产品参数'!C10+'产品参数'!E14-'盈亏平衡计算'!C13 | D13: =A13*'产品参数'!B10+D$4*'产品参数'!C10+'产品参数'!E14-'盈亏平衡计算'!C13 | E13: =A13*'产品参数'!B10+E$4*'产品参数'!C10+'产品参数'!E14-'盈亏平衡计算'!C13 | F13: =A13*'产品参数'!B10+F$4*'产品参数'!C10+'产品参数'!E14-'盈亏平衡计算'!C13 | G13: =A13*'产品参数'!B10+G$4*'产品参数'!C10+'产品参数'!E14-'盈亏平衡计算'!C13 | H13: =A13*'产品参数'!B10+H$4*'产品参数'!C10+'产品参数'!E14-'盈亏平衡计算'!C13 | I13: =A13*'产品参数'!B10+I$4*'产品参数'!C10+'产品参数'!E14-'盈亏平衡计算'!C13 | J13: =A13*'产品参数'!B10+J$4*'产品参数'!C10+'产品参数'!E14-'盈亏平衡计算'!C13 | K13: =A13*'产品参数'!B10+K$4*'产品参数'!C10+'产品参数'!E14-'盈亏平衡计算'!C13 | L13: =A13*'产品参数'!B10+L$4*'产品参数'!C10+'产品参数'!E14-'盈亏平衡计算'!C13
A14: 2250 | B14: =A14*'产品参数'!B10+B$4*'产品参数'!C10+'产品参数'!E14-'盈亏平衡计算'!C13 | C14: =A14*'产品参数'!B10+C$4*'产品参数'!C10+'产品参数'!E14-'盈亏平衡计算'!C13 | D14: =A14*'产品参数'!B10+D$4*'产品参数'!C10+'产品参数'!E14-'盈亏平衡计算'!C13 | E14: =A14*'产品参数'!B10+E$4*'产品参数'!C10+'产品参数'!E14-'盈亏平衡计算'!C13 | F14: =A14*'产品参数'!B10+F$4*'产品参数'!C10+'产品参数'!E14-'盈亏平衡计算'!C13 | G14: =A14*'产品参数'!B10+G$4*'产品参数'!C10+'产品参数'!E14-'盈亏平衡计算'!C13 | H14: =A14*'产品参数'!B10+H$4*'产品参数'!C10+'产品参数'!E14-'盈亏平衡计算'!C13 | I14: =A14*'产品参数'!B10+I$4*'产品参数'!C10+'产品参数'!E14-'盈亏平衡计算'!C13 | J14: =A14*'产品参数'!B10+J$4*'产品参数'!C10+'产品参数'!E14-'盈亏平衡计算'!C13 | K14: =A14*'产品参数'!B10+K$4*'产品参数'!C10+'产品参数'!E14-'盈亏平衡计算'!C13 | L14: =A14*'产品参数'!B10+L$4*'产品参数'!C10+'产品参数'!E14-'盈亏平衡计算'!C13
A15: 2500 | B15: =A15*'产品参数'!B10+B$4*'产品参数'!C10+'产品参数'!E14-'盈亏平衡计算'!C13 | C15: =A15*'产品参数'!B10+C$4*'产品参数'!C10+'产品参数'!E14-'盈亏平衡计算'!C13 | D15: =A15*'产品参数'!B10+D$4*'产品参数'!C10+'产品参数'!E14-'盈亏平衡计算'!C13 | E15: =A15*'产品参数'!B10+E$4*'产品参数'!C10+'产品参数'!E14-'盈亏平衡计算'!C13 | F15: =A15*'产品参数'!B10+F$4*'产品参数'!C10+'产品参数'!E14-'盈亏平衡计算'!C13 | G15: =A15*'产品参数'!B10+G$4*'产品参数'!C10+'产品参数'!E14-'盈亏平衡计算'!C13 | H15: =A15*'产品参数'!B10+H$4*'产品参数'!C10+'产品参数'!E14-'盈亏平衡计算'!C13 | I15: =A15*'产品参数'!B10+I$4*'产品参数'!C10+'产品参数'!E14-'盈亏平衡计算'!C13 | J15: =A15*'产品参数'!B10+J$4*'产品参数'!C10+'产品参数'!E14-'盈亏平衡计算'!C13 | K15: =A15*'产品参数'!B10+K$4*'产品参数'!C10+'产品参数'!E14-'盈亏平衡计算'!C13 | L15: =A15*'产品参数'!B10+L$4*'产品参数'!C10+'产品参数'!E14-'盈亏平衡计算'!C13
A17: 图例: | B17: 绿色=盈利
B18: 红色=亏损
A20: 当前利润 | B20: ='产品参数'!B18-'盈亏平衡计算'!C13
A21: 当前120销量 | B21: ='产品参数'!B6
A22: 当前155销量 | B22: ='产品参数'!C6

Sheet 可视化
A1: 盈亏平衡可视化（A.本量利 B.利润曲线 C.等利润线）
A2: * 数据全部公式引用，改Sheet1/Sheet2 -> 图表自动更新
A4: 关键参数（引用盈亏平衡计算）
A5: BEP收入 | B5: ='盈亏平衡计算'!B20
A6: 需弥补缺口 | B6: ='盈亏平衡计算'!B18
A7: 变动成本率(1-CMR) | B7: =1-'盈亏平衡计算'!B19
A8: 当前120&155收入 | B8: ='产品参数'!B20
A10: 产能利用率 | B10: 120&155收入 | C10: 变动成本 | D10: 需覆盖成本(VC+缺口) | E10: 缺口线
A11: 0% | B11: =B5*0.0 | C11: =B11*B7 | D11: =C11+B6 | E11: =B6
A12: 20% | B12: =B5*0.2 | C12: =B12*B7 | D12: =C12+B6 | E12: =B6
A13: 40% | B13: =B5*0.4 | C13: =B13*B7 | D13: =C13+B6 | E13: =B6
A14: 60% | B14: =B5*0.6 | C14: =B14*B7 | D14: =C14+B6 | E14: =B6
A15: 80% | B15: =B5*0.8 | C15: =B15*B7 | D15: =C15+B6 | E15: =B6
A16: 100% | B16: =B5*1.0 | C16: =B16*B7 | D16: =C16+B6 | E16: =B6
A17: 120% | B17: =B5*1.2 | C17: =B17*B7 | D17: =C17+B6 | E17: =B6
A18: 140% | B18: =B5*1.4 | C18: =B18*B7 | D18: =C18+B6 | E18: =B6
A19: v BEP点 | B19: =B5 | C19: =B5*B7 | D19: =B5 | E19: =B6
A20: * 当前位置 | B20: =B8 | C20: =B20*B7 | D20: =C20+B6 | E20: =B6
A42: 图B: 利润-收入曲线数据
A43: 120&155收入 | B43: 利润 | C43: 零利润线 | D43: 标记
A44: 0 | B44: =A44*'盈亏平衡计算'!B19-'盈亏平衡计算'!B18 | C44: 0
A45: 500000 | B45: =A45*'盈亏平衡计算'!B19-'盈亏平衡计算'!B18 | C45: 0
A46: 1000000 | B46: =A46*'盈亏平衡计算'!B19-'盈亏平衡计算'!B18 | C46: 0
A47: 1500000 | B47: =A47*'盈亏平衡计算'!B19-'盈亏平衡计算'!B18 | C47: 0
A48: 2000000 | B48: =A48*'盈亏平衡计算'!B19-'盈亏平衡计算'!B18 | C48: 0
A49: 2500000 | B49: =A49*'盈亏平衡计算'!B19-'盈亏平衡计算'!B18 | C49: 0
A50: 3000000 | B50: =A50*'盈亏平衡计算'!B19-'盈亏平衡计算'!B18 | C50: 0
A51: 3500000 | B51: =A51*'盈亏平衡计算'!B19-'盈亏平衡计算'!B18 | C51: 0
A52: 4000000 | B52: =A52*'盈亏平衡计算'!B19-'盈亏平衡计算'!B18 | C52: 0
A53: 4500000 | B53: =A53*'盈亏平衡计算'!B19-'盈亏平衡计算'!B18 | C53: 0
A54: 5000000 | B54: =A54*'盈亏平衡计算'!B19-'盈亏平衡计算'!B18 | C54: 0
A55: 5500000 | B55: =A55*'盈亏平衡计算'!B19-'盈亏平衡计算'!B18 | C55: 0
A56: 6000000 | B56: =A56*'盈亏平衡计算'!B19-'盈亏平衡计算'!B18 | C56: 0
A57: 6500000 | B57: =A57*'盈亏平衡计算'!B19-'盈亏平衡计算'!B18 | C57: 0
A58: 7000000 | B58: =A58*'盈亏平衡计算'!B19-'盈亏平衡计算'!B18 | C58: 0
A59: 7500000 | B59: =A59*'盈亏平衡计算'!B19-'盈亏平衡计算'!B18 | C59: 0
A60: 8000000 | B60: =A60*'盈亏平衡计算'!B19-'盈亏平衡计算'!B18 | C60: 0
A61: 8500000 | B61: =A61*'盈亏平衡计算'!B19-'盈亏平衡计算'!B18 | C61: 0
A62: 9000000 | B62: =A62*'盈亏平衡计算'!B19-'盈亏平衡计算'!B18 | C62: 0
A63: 9500000 | B63: =A63*'盈亏平衡计算'!B19-'盈亏平衡计算'!B18 | C63: 0
...
